Workbook
Name AcucarNY2010: #REF!
Name AcucarSP2010: #REF!
Name AcucarSP2010Defl: Cana!AcucarSP2010*#REF!
Name AcucarSP2010USD: #REF!/#REF!
Name AcucarSP2015: #REF!
Name Argentina1990: #REF!
Name Argentina2000: #REF!
Name Argentina2010: #REF!
Name Argentina2015: #REF!
Name AtacadoSP1995Defl: #REF!*#REF!
Name Beef2010: #REF!
Name BezerroMS2000Defl: #REF!*#REF!
Name BoiSP2000Defl: #REF!*#REF!
Name BoiSP2010: #REF!
Name BoiSP2010Defl: #REF!*#REF!
Name BoiSP2010DeflKg: #REF!*#REF!/30
Name BoiSP2010USD: #REF!/#REF!
Name BoiSPEvolPrecos: #REF!
Name BrentOil2000: #REF!
Name BrentOil2010: #REF!
Name CafeArabSP1995: #REF!
Name CafeArabSP1995Defl: 'Demais AGRÍCOLAS'!CafeArabSP1995*#REF!
Name CafeArabSP2010: #REF!
Name CafeArabSP2010Defl: #REF!*#REF!
Name CafeArabSP2010USD: #REF!/#REF!
Name CafeDifArabRobu2010: 'Demais AGRÍCOLAS'!CafeArabSP2010-'Demais AGRÍCOLAS'!CafeRobuSP2010
Name CafeNY2010: #REF!
Name CafeRobuSP2010: #REF!
Name CafeRobuSP2010USD: #REF!/#REF!
Name CafeRobustaSP2010Defl: #REF!*#REF!
Name CafeRobustaSP2010USD: #REF!/#REF!
Name CanaSP2010Defl: #REF!*#REF!
Name CanaSP2010USD: #REF!/#REF!
Name CarnesEvol: 'PECUÁRIA Charts'!$R$18:$U$22
Name CBOT1990ton: #REF!*39.37
Name CBOT1990USD: #REF!/100
Name CBOT1990USDsaca: #REF!/45.36
Name CBOT1990USDton: #REF!*0.367437
Name CBOT2000bu: #REF!
Name CBOT2000PlusPremium: Soja!CBOT2000USD+Soja!PremioPR2000
Name CBOT2000USD: ROUND(#REF!/100,2)
Name CBOT2010bu: #REF!
Name CBOT2010USDsaca: #REF!/45.36
Name CBOT2010USDton: #REF!*0.367437
Name ChickenMeat2010: #REF!
Name Cotlook2010: #REF!
Name Cotlook2015: #REF!
Name Culturas: {"Soja";"Trigo"}
Name DDG_MT2020: #REF!
Name DDG_MT2020Defl: #REF!*#REF!
Name DDG_MT2020USD: #REF!/#REF!
Name desde1990: #REF!
Name desde1995: #REF!
Name desde2000: #REF!
Name desde2010: #REF!
Name desde2013: #REF!
Name desde2015: #REF!
Name desde2020: #REF!
Name ESALQ2000Arroba: #REF!*33.11258
Name ESALQ2000centsLB: #REF!*100/#REF!

Sheet Capa
U4: Data de atualização: | V4: 46296
B24: instagram.com/carloscogo
B25: www.carloscogo.com.br
B26: consultoria@carloscogo.com.br
B27: +55 51 3248 1117 | +55 51 999 867 666

Sheet Evolução de Preços
A3: COMMODITY | B3: AÇÚCAR | C3: AÇÚCAR | D3: ALGODÃO | E3: ALGODÃO | F3: ALGODÃO | G3: ARROZ | H3: ARROZ | I3: ARROZ T1 | J3: ARROZ T1 | K3: ARROZ 100B | L3: ARROZ US/4 | M3: CAFÉ | N3: CAFÉ | O3: CAFÉ | P3: CANA | Q3: ETANOL | R3: ETANOL | S3: FEIJÃO | T3: LARANJA | U3: LARANJA | V3: MILHO | W3: MILHO | X3: MILHO | Y3: MILHO | Z3: MILHO | AA3: MILHO | AB3: MILHO | AC3: MILHO | AD3: MILHO | AE3: MILHO | AF3: DDG MILHO | AG3: SOJA | AH3: SOJA | AI3: SOJA | AJ3: SOJA | AK3: SOJA | AL3: SOJA | AM3: FARELO SOJA | AN3: FARELO SOJA | AO3: ÓLEO SOJA | AP3: OLEO SOJA | AQ3: SORGO | AR3: TRIGO | AS3: TRIGO | AT3: TRIGO | AU3: TRIGO | AV3: TRIGO | AW3: BEZERRO | AX3: BOI GORDO | AY3: BEEF | AZ3: FRANGO | BA3: FRANGO | BB3: CHICKEN MEAT | BC3: LEITE | BD3: LEITE | BE3: LEITE | BF3: LEITE | BG3: LEITE | BH3: LEITE | BI3: LEITE | BJ3: SUÍNO | BK3: SUÍNO | BL3: OVOS | BM3: TILÁPIA | BN3: BRENT | BO3: NATURAL GAS | BP3: DIESEL S-10 | BQ3: E. HIDRATADO | BR3: GASOLINA C | BS3: Food | BT3: Meat | BU3: Dairy | BV3: Cereals | BW3: Oils | BX3: Sugar | BY3: DÓLAR
A4: REFERÊNCIA | B4: ATACADO | C4: ICE NY | D4: ICE US | E4: COTLOOK 'A' | F4: ESALQ | G4: RS | H4: MT | I4: ATACADO SP | J4: VAREJO SP | K4: TAILÂNDIA | L4: EUA | M4: ARÁBICA SP | N4: ICE US | O4: CONILON SP | P4: SP | Q4: ANIDRO | R4: HIDRATADO | S4: CORES - SP | T4: INDÚSTRIA SP | U4: MESA SP | V4: ATACADO SP | W4: GO | X4: MS | Y4: MT | Z4: PR | AA4: RS | AB4: CBOT | AC4: GOLFO EUA | AD4: ARGENTINA | AE4: PARANAGUÁ | AF4: 32% PB - MT | AG4: MT | AH4: PR | AI4: PARANAGUÁ | AJ4: RS | AK4: CHICAGO | AL4: PRÊMIO | AM4: ATACADO SP | AN4: CHICAGO | AO4: ATACADO SP | AP4: CHICAGO | AQ4: GO | AR4: PR | AS4: RS | AT4: ARGENTINA | AU4: US SRW | AV4: US HRW | AW4: MS | AX4: SP | AY4: World Bank | AZ4: VIVO SP | BA4: RESFRIADO SP | BB4: World Bank | BC4: BRASIL | BD4: GO | BE4: MG | BF4: PR | BG4: RS | BH4: SC | BI4: SP | BJ4: VIVO SC | BK4: CARCAÇA | BL4: BRANCOS SP | BM4: NORTE PR | BN4: GLOBAL | BO4: EUROPE | BP4: VAREJO BR | BQ4: VAREJO BR | BR4: VAREJO BR | BS4: FAO | BT4: FAO | BU4: FAO | BV4: FAO | BW4: FAO | BX4: FAO | BY4: COMERCIAL
A5: UNIDADE | B5: R$/50 kg | C5: ¢/lb | D5: ¢/lb | E5: ¢/lb | F5: R$/lb | G5: R$/50 kg | H5: R$/60 kg | I5: R$/30 kg | J5: R$/kg | K5: US$/t | L5: US$/t | M5: R$/60 kg | N5: ¢/lb | O5: R$/60 kg | P5: R$/t | Q5: R$/l | R5: R$/l | S5: R$/60 kg | T5: R$/40,8 kg | U5: R$/40,8 kg | V5: R$/60 kg | W5: R$/60 kg | X5: R$/60 kg | Y5: R$/60 kg | Z5: R$/60 kg | AA5: R$/60 kg | AB5: US$/bu | AC5: US$/t | AD5: US$/t | AE5: US$/t | AF5: R$/t | AG5: R$/60 kg | AH5: R$/60 kg | AI5: R$/60 kg | AJ5: R$/60 kg | AK5: ¢/bushel | AL5: US$/bu | AM5: R$/t | AN5: US$/t | AO5: R$/t | AP5: US$/t | AQ5: R$/60 kg | AR5: R$/60 kg | AS5: R$/60 kg | AT5: US$/t | AU5: US$/t | AV5: US$/t | AW5: R$/un | AX5: R$/@ 30 DIAS | AY5: US$/kg | AZ5: R$/kg vivo | BA5: R$/kg | BB5: US$/kg | BC5: R$/l | BD5: R$/l | BE5: R$/l | BF5: R$/l | BG5: R$/l | BH5: R$/l | BI5: R$/l | BJ5: R$/kg vivo | BK5: R$/kg | BL5: R$/CX 30 DZ | BM5: R$/kg | BN5: US$/barril | BO5: US$/mmbtu | BP5: R$/l | BQ5: R$/l | BR5: R$/l | BS5: Price Index | BT5: Price Index | BU5: Price Index | BV5: Price Index | BW5: Price Index | BX5: Price Index | BY5: VENDA
A6: ÚLTIMOS 30 DIAS | B6: 0.090695361 | C6: -0.027322404 | D6: -0.11395477 | E6: -0.046286877 | F6: -0.023270872 | G6: 0.059609455 | H6: 0 | I6: 0 | J6: 0 | K6: 0.032967033 | L6: 0.018181818 | M6: -0.11731138 | N6: -0.18479988 | O6: -0.067698206 | P6: -0.01371376 | Q6: 0 | R6: 0.14419924 | S6: 0.15954633 | T6: -0.059332906 | U6: -0.0070762303 | V6: 0.0086893555 | W6: 0 | X6: 0.066666667 | Y6: 0.031578947 | Z6: 0.032786885 | AA6: 0.014925373 | AB6: 0.035276825 | AC6: 0.0084638345 | AD6: 0.0045045045 | AE6: -0.035644637 | AF6: 0.022920204 | AG6: 0.048689139 | AH6: 0.034649152 | AI6: 0.038374718 | AJ6: 0.055172414 | AK6: 0.049741345 | AL6: -0.125 | AM6: 0.14298772 | AN6: 0.13901863 | AO6: 0.029752003 | AP6: -0.015735793 | AQ6: 0 | AR6: 0.023382697 | AS6: 0.05518131 | AT6: 0.047808765 | AU6: 0.13358663 | AV6: 0.032181818 | AW6: 0.0054213755 | AX6: 0.041509434 | AY6: -0.0041208791 | AZ6: 0.0042194093 | BA6: 0.12735166 | BB6: -0.0059171598 | BC6: 0 | BD6: 0 | BE6: 0 | BF6: 0 | BG6: 0 | BH6: 0 | BI6: 0 | BJ6: 0.10805085 | BK6: 0.11653117 | BL6: 0.016839378 | BM6: 0 | BN6: 0.16298774 | BO6: 0.0042633823 | BP6: 0.063860668 | BQ6: 0.04859335 | BR6: 0.004601227 | BS6: 0 | BT6: 0 | BU6: 0 | BV6: 0 | BW6: 0 | BX6: 0 | BY6: 0.007751938
A7: EM 2026 | B7: 0.1298239 | C7: 0.20596206 | D7: 0.23455272 | E7: 0.2746431 | F7: 0.18261654 | G7: 0.54775755 | H7: 0.6 | I7: -0.037469921 | J7: 0.014285714 | K7: 0.18987342 | L7: -0.0088495575 | M7: -0.31250615 | N7: -0.24541929 | O7: -0.24744903 | P7: -0.19410393 | Q7: -0.25955921 | R7: -0.15065789 | S7: 0.52121291 | T7: -0.20793951 | U7: -0.27227723 | V7: 0.0075220599 | W7: 0 | X7: -0.01754386 | Y7: -0.08411215 | Z7: -0.0078740157 | AA7: 0.014925373 | AB7: 0.18975225 | AC7: 0.13910955 | AD7: 0.0045045045 | AE7: 0.0054712893 | AF7: 0.082095584 | AG7: 0.30841121 | AH7: 0.18199219 | AI7: 0.19515997 | AJ7: 0.15909091 | AK7: 0.26583493 | AL7: -0.58210204 | AM7: 0.23447136 | AN7: 0.27621979 | AO7: 0.070178654 | AP7: 0.36592455 | AQ7: 0.076053685 | AR7: 0.10826004 | AS7: 0.17687682 | AT7: 0.2705314 | AU7: 0.37050988 | AV7: 0.36302521 | AW7: 0.12053797 | AX7: 0.11245466 | AY7: -0.09033877 | AZ7: -0.13296903 | BA7: 0.001285347 | BB7: -0.04 | BC7: 0.42461417 | BD7: 0.53204794 | BE7: 0.4636747 | BF7: 0.42471137 | BG7: 0.32734531 | BH7: 0.42492339 | BI7: 0.41052432 | BJ7: -0.37214886 | BK7: -0.36074476 | BL7: 0.23488349 | BM7: -0.0039177277 | BN7: 0.56237831 | BO7: 0.80272109 | BP7: 0.20757825 | BQ7: -0.086859688 | BR7: 0.053054662 | BS7: 0.07380003 | BT7: 0.023792595 | BU7: -0.014152134 | BV7: 0.081676858 | BW7: 0.16726372 | BX7: 0.18423268 | BY7: -0.033457249
A8: 12 MESES | B8: 0.018405944 | C8: 0.12944162 | D8: 0.21182861 | E8: 0.19961612 | F8: 0.15277236 | G8: 0.35346242 | H8: 0.34265734 | I8: -0.17671273 | J8: -0.079913607 | K8: 0.32394366 | L8: -0.066666667 | M8: -0.27503205 | N8: -0.2403393 | O8: -0.26083698 | P8: -0.30802015 | Q8: -0.20496894 | R8: -0.061090909 | S8: 0.38555455 | T8: -0.4134 | U8: -0.48082745 | V8: 0.082193909 | W8: 0.094339623 | X8: 0.018181818 | Y8: 0.042553191 | Z8: 0.05 | AA8: -0.028571429 | AB8: 0.24075161 | AC8: 0.19392003 | AD8: 0.115 | AE8: 0.04974359 | AF8: 0.070559178 | AG8: 0.19148936 | AH8: 0.20336737 | AI8: 0.20230005 | AJ8: 0.18604651 | AK8: 0.30303779 | AL8: -0.80556136 | AM8: 0.3725466 | AN8: 0.40022967 | AO8: -0.072723784 | AP8: 0.34559581 | AQ8: 0 | AR8: 0.027362425 | AS8: -0.0017979027 | AT8: 0.1793722 | AU8: 0.44164014 | AV8: 0.45713552 | AW8: 0.17346783 | AX8: 0.1737765 | AY8: 0.050609071 | AZ8: -0.13924051 | BA8: -0.044171779 | BB8: -0.036569085 | BC8: 0.18032787 | BD8: 0.25641026 | BE8: 0.19367589 | BF8: 0.17886179 | BG8: 0.12711864 | BH8: 0.19230769 | BI8: 0.16015625 | BJ8: -0.36759371 | BK8: -0.3785822 | BL8: -0.13943131 | BM8: 0 | BN8: 0.50273696 | BO8: 0.90710675 | BP8: 0.20957096 | BQ8: -0.044289044 | BR8: 0.056451613 | BS8: 0.036710952 | BT8: 0.0002240848 | BU8: -0.18984027 | BV8: 0.10944126 | BW8: 0.17228415 | BX8: 0.070397006 | BY8: -0.026217228
A9: 24 MESES | B9: -0.145327 | C9: -0.23407917 | D9: 0.10435859 | E9: 0.10424028 | F9: 0.05665474 | G9: -0.30584077 | H9: -0.30434783 | I9: -0.42118863 | J9: -0.3014103 | K9: 0 | L9: -0.27272727 | M9: 0.044519362 | N9: 0.11922238 | O9: -0.36377466 | P9: -0.26370757 | Q9: -0.096746877 | R9: 0.052846191 | S9: 0.44148477 | T9: -0.65400495 | U9: -0.73179844 | V9: 0.11261981 | W9: 0.035714286 | X9: -0.0088495575 | Y9: 0.11363636 | Z9: 0.024390244 | AA9: 0.014925373 | AB9: 0.23350846 | AC9: 0.16394526 | AD9: 0.082524272 | AE9: 0.11104991 | AF9: 0.075067359 | AG9: 0.085271318 | AH9: 0.12974753 | AI9: 0.15082202 | AJ9: 0.15037594 | AK9: 0.26099426 | AL9: -0.78362316 | AM9: 0.068291926 | AN9: 0.13010767 | AO9: 0.10263536 | AP9: 0.49764524 | AQ9: 0 | AR9: -0.11353663 | AS9: -0.10032995 | AT9: 0.069105691 | AU9: 0.36109794 | AV9: 0.26300567 | AW9: 0.65272026 | AX9: 0.39296529 | AY9: 0.151517 | AZ9: -0.10018904 | BA9: 0.04144385 | BB9: 0.1562086 | BC9: 0.0049900548 | BD9: 0.046524045 | BE9: 0.0091221973 | BF9: -0.0061004867 | BG9: -0.02133922 | BH9: -0.005702067 | BI9: 0.045038705 | BJ9: -0.37663886 | BK9: -0.36858238 | BL9: 0.032300485 | BM9: 0 | BN9: 0.34398351 | BO9: 0.79900999 | BP9: 0.21963394 | BQ9: 0.014851485 | BR9: 0.07907743 | BS9: 0.060607028 | BT9: 0.057616745 | BU9: -0.13426386 | BV9: 0.014974318 | BW9: 0.37089094 | BX9: -0.16461539 | BY9: -0.045521292

Sheet Evolução Charts

Sheet Algodão
C4: Algodão | D4: Algodão | E4: Algodão | F4: Algodão | G4: Algodão | H4: Algodão | I4: Algodão
A5: Ano | B5: Mês | C5: Indicador Esalq | D5: Indicador Esalq | E5: Indicador Esalq | F5: Indicador Esalq | G5: Indicador Esalq | H5: Futuro NY ICE | I5: Cotlook A Index
C6: R$/libra-peso | D6: ¢/libra-peso | E6: R$/@ | F6: US$/@ | G6: Deflacionado | H6: ¢/libra-peso | I6: ¢/libra-peso
A7: 1990 | B7: JAN
B8: FEV
B9: MAR
B10: ABR
B11: MAI
B12: JUN
B13: JUL
B14: AGO
B15: SET
B16: OUT
B17: NOV
B18: DEZ
A19: 1991 | B19: JAN
B20: FEV
B21: MAR
B22: ABR
B23: MAI
B24: JUN
B25: JUL
B26: AGO
B27: SET
B28: OUT
B29: NOV
B30: DEZ
A31: 1992 | B31: JAN
B32: FEV
B33: MAR
B34: ABR
B35: MAI
B36: JUN
B37: JUL
B38: AGO
B39: SET
B40: OUT
B41: NOV
B42: DEZ
A43: 1993 | B43: JAN
...

Sheet Algodão Charts

Sheet Arroz
C4: Arroz em casca | D4: Arroz em casca | E4: Arroz em casca | F4: Arroz em casca | G4: Arroz em casca | H4: Arroz Beneficiado | I4: Arroz Beneficiado | J4: Arroz Beneficiado | K4: Arroz Beneficiado | L4: Arroz Beneficiado | M4: Arroz Beneficiado | N4: Arroz Beneficiado | O4: Arroz Beneficiado
A5: Ano | B5: Mês | C5: RS | D5: RS | E5: RS | F5: MT | G5: MT | H5: Atacado SP - T1 | I5: Atacado SP - T1 | J5: Atacado SP - T1 | K5: Varejo SP - T1 | L5: Varejo SP - T1 | M5: Varejo SP - T1 | N5: Tailândia WR100B | O5: EUA US/4
C6: R$/50 kg | D6: US$/50 kg | E6: Deflacionado | F6: R$/60 kg | G6: US$/60 kg | H6: R$/30 kg | I6: US$/30 kg | J6: Deflacionado | K6: R$/kg | L6: US$/kg | M6: Deflacionado | N6: US$/t FOB | O6: US$/t FOB
A7: 1990 | B7: JAN | C7: 136 | D7: 9.5011876 | F7: 140.9929 | G7: 9.85 | H7: 606 | I7: 42.336174 | K7: 15.2 | L7: 1.0618974 | N7: 301.59 | O7: 338
B8: FEV | C8: 265 | D8: 11.199865 | F8: 282.03912 | G8: 11.92 | H8: 613.75 | I8: 25.939309 | K8: 27.13 | L8: 1.1466126 | N8: 300 | O8: 356
B9: MAR | C9: 316.5 | D9: 8.3849944 | F9: 414.45108 | G9: 10.98 | H9: 828 | I9: 21.936099 | K9: 30.63 | L9: 0.81147671 | N9: 297.27 | O9: 348
B10: ABR | C10: 374 | D10: 7.8216497 | F10: 435.1256 | G10: 9.1 | H10: 890 | I10: 18.613017 | K10: 29.28 | L10: 0.61234733 | N10: 288.25 | O10: 342
B11: MAI | C11: 476.5 | D11: 9.1278279 | F11: 541.86714 | G11: 10.38 | H11: 920 | I11: 17.623508 | K11: 30.4 | L11: 0.58234201 | N11: 280 | O11: 338
B12: JUN | C12: 567 | D12: 9.9176156 | F12: 701.48817 | G12: 12.27 | H12: 990 | I12: 17.316472 | K12: 30.5 | L12: 0.53348726 | N12: 270.48 | O12: 336
B13: JUL | C13: 584.5 | D13: 8.7745635 | F13: 835.32702 | G13: 12.54 | H13: 1413.75 | I13: 21.223335 | K13: 33.13 | L13: 0.49735037 | N13: 258.41 | O13: 333
B14: AGO | C14: 621 | D14: 8.6560174 | F14: 859.46916 | G14: 11.98 | H14: 2157 | I14: 30.06607 | K14: 34 | L14: 0.47392044 | N14: 255 | O14: 306
B15: SET | C15: 808 | D15: 10.659209 | F15: 924.03857 | G15: 12.19 | H15: 3062.5 | I15: 40.400776 | K15: 40.88 | L15: 0.53929264 | N15: 251.25 | O15: 287
B16: OUT | C16: 1068 | D16: 11.189925 | F16: 983.0629 | G16: 10.3 | H16: 3075 | I16: 32.218183 | K16: 66 | L16: 0.69151221 | N16: 255 | O16: 284
B17: NOV | C17: 1514 | D17: 12.422054 | F17: 1193.2052 | G17: 9.79 | H17: 4766 | I17: 39.104037 | K17: 101.25 | L17: 0.83073515 | N17: 260 | O17: 314
B18: DEZ | C18: 1997.5 | D18: 12.844338 | F18: 1702.9002 | G18: 10.95 | H18: 5600 | I18: 36.009157 | K18: 122.5 | L18: 0.7877003 | N18: 260 | O18: 325
A19: 1991 | B19: JAN | C19: 2266.5 | D19: 10.295721 | F19: 2031.8922 | G19: 9.23 | H19: 5450 | I19: 24.756973 | K19: 170 | L19: 0.77223585 | N19: 310 | O19: 333
B20: FEV | C20: 3634.5 | D20: 16.26684 | F20: 2683.3943 | G20: 12.01 | H20: 5000 | I20: 22.378374 | K20: 210.75 | L20: 0.94324844 | N20: 353 | O20: 349
B21: MAR | C21: 3819 | D21: 15.983761 | F21: 2946.0069 | G21: 12.33 | H21: 5430 | I21: 22.726322 | K21: 211 | L21: 0.88310384 | N21: 348 | O21: 364
B22: ABR | C22: 5561 | D22: 21.328577 | F22: 3136.5819 | G22: 12.03 | H22: 5400 | I22: 20.71108 | K22: 209.5 | L22: 0.80351321 | N22: 318 | O22: 372
B23: MAI | C23: 3850.8333 | D23: 13.525934 | F23: 3174.405 | G23: 11.15 | H23: 5385 | I23: 18.914647 | K23: 220.6 | L23: 0.77485072 | N23: 320 | O23: 380
B24: JUN | C24: 3819.5 | D24: 12.232969 | F24: 3209.7244 | G24: 10.28 | H24: 6525 | I24: 20.898056 | K24: 221.75 | L24: 0.71021362 | N24: 303 | O24: 389
B25: JUL | C25: 3801 | D25: 10.967481 | F25: 3261.2237 | G25: 9.41 | H25: 7912.5 | I25: 22.830886 | K25: 225 | L25: 0.64921949 | N25: 310 | O25: 383
B26: AGO | C26: 4348.5 | D26: 11.596 | F26: 3435 | G26: 9.16 | H26: 11360 | I26: 30.293333 | K26: 254.25 | L26: 0.678 | N26: 325 | O26: 369
B27: SET | C27: 5284.5 | D27: 12.010227 | F27: 4012.8 | G27: 9.12 | H27: 12500 | I27: 28.409091 | K27: 273.38 | L27: 0.62131818 | N27: 325 | O27: 378
B28: OUT | C28: 7727.5 | D28: 12.879167 | F28: 5088 | G28: 8.48 | H28: 13437.5 | I28: 22.395833 | K28: 423 | L28: 0.705 | N28: 300 | O28: 383
B29: NOV | C29: 8707.5 | D29: 11.533113 | F29: 7081.9 | G29: 9.38 | H29: 17600 | I29: 23.311258 | K29: 540 | L29: 0.71523179 | N29: 300 | O29: 386
B30: DEZ | C30: 9216 | D30: 9.4233129 | F30: 8361.9 | G30: 8.55 | H30: 17600 | I30: 17.99591 | K30: 608.75 | L30: 0.62244376 | N30: 305 | O30: 386
A31: 1992 | B31: JAN | C31: 9664 | D31: 8.0735171 | F31: 10066.77 | G31: 8.41 | H31: 17600 | I31: 14.703425 | K31: 664 | L31: 0.55472013 | N31: 300 | O31: 380
B32: FEV | C32: 13266.5 | D32: 9.0003392 | F32: 11570.9 | G32: 7.85 | H32: 19375 | I32: 13.144505 | K32: 821.25 | L32: 0.55715739 | N32: 300 | O32: 372
B33: MAR | C33: 13618 | D33: 7.5113072 | F33: 13343.68 | G33: 7.36 | H33: 20680 | I33: 11.406509 | K33: 791.88 | L33: 0.43677882 | N33: 300 | O33: 365
B34: ABR | C34: 14896 | D34: 6.7189896 | F34: 14898.24 | G34: 6.72 | H34: 23500 | I34: 10.59991 | K34: 907.5 | L34: 0.40933694 | N34: 305 | O34: 360
B35: MAI | C35: 19057 | D35: 7.3296154 | F35: 17706 | G35: 6.81 | H35: 31000 | I35: 11.923077 | K35: 1082.5 | L35: 0.41634615 | N35: 300 | O35: 340
B36: JUN | C36: 26601.5 | D36: 7.8239706 | F36: 19958 | G36: 5.87 | H36: 39250 | I36: 11.544118 | K36: 1485 | L36: 0.43676471 | N36: 305 | O36: 323
B37: JUL | C37: 28376.5 | D37: 7.3705195 | F37: 26911.5 | G37: 6.99 | H37: 44700 | I37: 11.61039 | K37: 1804 | L37: 0.46857143 | N37: 305 | O37: 320
B38: AGO | C38: 40500 | D38: 8.7096774 | F38: 37479 | G38: 8.06 | H38: 63500 | I38: 13.655914 | K38: 2203.75 | L38: 0.47392473 | N38: 305 | O38: 330
B39: SET | C39: 56150 | D39: 9.7516499 | F39: 46754.96 | G39: 8.12 | H39: 86800 | I39: 15.074679 | K39: 3173.8 | L39: 0.55119833 | N39: 300 | O39: 327
B40: OUT | C40: 64900 | D40: 8.8298118 | F40: 66003.898 | G40: 8.98 | H40: 106750 | I40: 14.523612 | K40: 4040.75 | L40: 0.54975443 | N40: 290 | O40: 329
B41: NOV | C41: 75150 | D41: 8.4701825 | F41: 88101.939 | G41: 9.93 | H41: 133000 | I41: 14.990476 | K41: 4870.75 | L41: 0.54898392 | N41: 285 | O41: 326
B42: DEZ | C42: 103400 | D42: 9.3542492 | F42: 111643.38 | G42: 10.1 | H42: 159400 | I42: 14.42038 | K42: 6036.1 | L42: 0.54606561 | N42: 275 | O42: 320
A43: 1993 | B43: JAN | C43: 128950 | D43: 9.1719301 | F43: 145372.13 | G43: 10.34 | H43: 193125 | I43: 13.736557 | K43: 7099 | L43: 0.50493627 | N43: 270 | O43: 314
...

Sheet Arroz Charts

Sheet Milho
C4: MILHO | D4: MILHO | E4: MILHO | F4: MILHO | G4: MILHO | H4: MILHO | I4: MILHO | J4: MILHO | K4: MILHO | L4: MILHO | M4: MILHO | N4: MILHO | O4: MILHO | P4: MILHO | Q4: MILHO | R4: MILHO | S4: MILHO | T4: MILHO | U4: MILHO | V4: MILHO | W4: MILHO | X4: MILHO | Y4: DDG | Z4: DDG | AA4: DDG | AB4: SORGO | AC4: SORGO | AD4: SORGO
A5: Ano | B5: Mês | C5: GO | D5: GO | E5: GO | F5: MS | G5: MS | H5: MS | I5: MT | J5: MT | K5: MT | L5: PR | M5: PR | N5: PR | O5: RS | P5: RS | Q5: RS | R5: SP | S5: SP | T5: SP | U5: CBOT | V5: EUA FOB Golfo | W5: Argentina FOB | X5: Paranaguá | Y5: MT | Z5: MT | AA5: MT | AB5: GO | AC5: GO | AD5: GO
C6: R$/60 kg | D6: US$/60 kg | E6: Deflacionado | F6: R$/60 kg | G6: US$/60 kg | H6: Deflacionado | I6: R$/60 kg | J6: US$/60 kg | K6: Deflacionado | L6: R$/60 kg | M6: US$/60 kg | N6: Deflacionado | O6: R$/60 kg | P6: US$/60 kg | Q6: Deflacionado | R6: R$/60 kg | S6: US$/60 kg | T6: Deflacionado | U6: US$/bushel | V6: US$/t | W6: US$/t | X6: US$/t | Y6: R$/t | Z6: US$/t | AA6: Deflacionado | AB6: R$/60 kg | AC6: US$/60 kg | AD6: Deflacionado
A7: 1990 | B7: JAN | C7: 94.5 | D7: 6.6019282 | L7: 108.5 | M7: 7.5799916 | O7: 69.6 | P7: 4.8623725 | R7: 108.5 | S7: 7.5799916 | U7: 2.3981 | V7: 94.409669 | W7: 104 | X7: 126.33
B8: FEV | C8: 135 | D8: 5.7055915 | L8: 156.25 | M8: 6.6036938 | O8: 129 | P8: 5.4520096 | R8: 172.5 | S8: 7.290478 | U8: 2.4135 | V8: 95.015944 | W8: 104 | X8: 121.51
B9: MAR | C9: 231.67 | D9: 6.137604 | L9: 243.33 | M9: 6.4465109 | O9: 208.8 | P9: 5.531712 | R9: 286.67 | S9: 7.594712 | U9: 2.5517 | V9: 100.45667 | W9: 105 | X9: 126.58
B10: ABR | C10: 238.75 | D10: 4.9930985 | L10: 281.25 | M10: 5.8819224 | O10: 261.6 | P10: 5.4709721 | R10: 277.5 | S10: 5.8034967 | U10: 2.735 | V10: 107.67293 | W10: 111 | X10: 96.72
B11: MAI | C11: 322 | D11: 6.1682279 | L11: 377.5 | M11: 7.2313852 | O11: 337.2 | P11: 6.4593989 | R11: 392 | S11: 7.509147 | U11: 2.846 | V11: 112.04283 | W11: 113 | X11: 125.15
B12: JUN | C12: 350 | D12: 6.1219849 | L12: 435 | M12: 7.6087527 | O12: 426.6 | P12: 7.4618251 | R12: 430 | S12: 7.5212958 | U12: 2.8542 | V12: 112.36565 | W12: 117 | X12: 125.35
B13: JUL | C13: 403.75 | D13: 6.0611292 | L13: 478.75 | M13: 7.1870356 | O13: 459.6 | P13: 6.8995541 | R13: 537.5 | S13: 8.0689955 | U13: 2.6867 | V13: 105.77143 | W13: 126 | X13: 134.48
B14: AGO | C14: 526 | D14: 7.3318279 | L14: 630 | M14: 8.7814669 | O14: 556.8 | P14: 7.7611441 | R14: 675 | S14: 9.4087146 | U14: 2.5111 | V14: 98.858313 | W14: 127 | X14: 156.81
B15: SET | C15: 582.5 | D15: 7.6843924 | L15: 668.75 | M15: 8.8222102 | O15: 637.8 | P15: 8.413915 | R15: 748.75 | S15: 9.8775774 | U15: 2.2946 | V15: 90.335026 | W15: 127 | X15: 164.63
B16: OUT | C16: 633 | D16: 6.6322308 | L16: 774 | M16: 8.1095523 | O16: 687 | P16: 7.1980135 | R16: 806 | S16: 8.4448309 | U16: 2.2979 | V16: 90.464942 | W16: 128 | X16: 140.75
B17: NOV | C17: 823.75 | D17: 6.7586971 | L17: 981.25 | M17: 8.0509518 | O17: 816.6 | P17: 6.7000328 | R17: 1019.75 | S17: 8.3668362 | U17: 2.2598 | V17: 88.965001 | W17: 128 | X17: 139.45
B18: DEZ | C18: 868.75 | D18: 5.5862419 | L18: 1075 | M18: 6.912472 | O18: 1115.4 | P18: 7.1722524 | R18: 1200 | S18: 7.7162478 | U18: 2.3647 | V18: 93.09476 | W18: 128 | X18: 128.6
A19: 1991 | B19: JAN | C19: 1045 | D19: 4.7469792 | L19: 1180 | M19: 5.3602253 | O19: 1150.8 | P19: 5.2275824 | R19: 1290 | S19: 5.8599073 | U19: 2.3752 | V19: 93.50813 | W19: 97 | X19: 97.67
B20: FEV | C20: 1197.5 | D20: 5.3596205 | L20: 1281.25 | M20: 5.7344582 | O20: 1311 | P20: 5.8676095 | R20: 1406.25 | S20: 6.2939176 | U20: 2.4031 | V20: 94.606512 | W20: 98 | X20: 104.9
B21: MAR | C21: 1156.25 | D21: 4.8392835 | L21: 1427.5 | M21: 5.9745532 | O21: 1369.2 | P21: 5.7305487 | R21: 1393.75 | S21: 5.8332985 | U21: 2.5403 | V21: 100.00787 | W21: 99 | X21: 97.22
B22: ABR | C22: 1450 | D22: 5.5613086 | L22: 1777.5 | M22: 6.8173973 | O22: 1565.4 | P22: 6.0039121 | R22: 1587.5 | S22: 6.0886741 | U22: 2.5555 | V22: 100.60628 | W22: 103 | X22: 101.48
B23: MAI | C23: 1645 | D23: 5.7780119 | L23: 1995 | M23: 7.0073762 | O23: 1879.8 | P23: 6.6027397 | R23: 1865 | S23: 6.5507552 | U23: 2.4909 | V23: 98.063068 | W23: 103 | X23: 109.18
B24: JUN | C24: 1568.75 | D24: 5.024341 | L24: 1987.5 | M24: 6.3654998 | O24: 1896.6 | P24: 6.0743683 | R24: 1893.75 | S24: 6.0652404 | U24: 2.3949 | V24: 94.28369 | W24: 105 | X24: 101.09
B25: JUL | C25: 1805 | D25: 5.2081831 | L25: 2280 | M25: 6.5787575 | O25: 2026.8 | P25: 5.8481692 | R25: 2220 | S25: 6.4056323 | U25: 2.354 | V25: 92.673517 | W25: 105 | X25: 106.76
B26: AGO | C26: 2258.75 | D26: 6.0233333 | L26: 2718.75 | M26: 7.25 | O26: 2248.8 | P26: 5.9968 | R26: 2831.25 | S26: 7.55 | U26: 2.4944 | V26: 98.200858 | W26: 106 | X26: 125.83
B27: SET | C27: 2568.75 | D27: 5.8380682 | L27: 3118.75 | M27: 7.0880682 | O27: 2709 | P27: 6.1568182 | R27: 3125 | S27: 7.1022727 | U27: 2.5151 | V27: 99.015787 | W27: 108 | X27: 118.37
B28: OUT | C28: 3890 | D28: 6.4833333 | L28: 4630 | M28: 7.7166667 | O28: 3567.6 | P28: 5.946 | R28: 4560 | S28: 7.6 | U28: 2.5086 | V28: 98.759891 | W28: 116 | X28: 126.67
B29: NOV | C29: 4887.5 | D29: 6.4735099 | L29: 5237.5 | M29: 6.9370861 | O29: 4961.4 | P29: 6.5713907 | R29: 5693.75 | S29: 7.5413907 | U29: 2.4343 | V29: 95.83481 | W29: 124 | X29: 125.69
B30: DEZ | C30: 5762.5 | D30: 5.8921268 | L30: 6212.5 | M30: 6.3522495 | O30: 5493.6 | P30: 5.6171779 | R30: 6837.5 | S30: 6.9913088 | U30: 2.5113 | V30: 98.866186 | W30: 122 | X30: 116.52
A31: 1992 | B31: JAN | C31: 8554 | D31: 7.1461988 | L31: 8230 | M31: 6.8755221 | O31: 5635.8 | P31: 4.7082707 | R31: 9840 | S31: 8.2205514 | U31: 2.5852 | V31: 101.77552 | W31: 114 | X31: 137.01
B32: FEV | C32: 8675 | D32: 5.885346 | L32: 8812.5 | M32: 5.9786296 | O32: 7901.4 | P32: 5.3605156 | R32: 10193 | S32: 6.9151967 | U32: 2.6457 | V32: 104.15732 | W32: 105 | X32: 115.25
B33: MAR | C33: 9050 | D33: 4.9917264 | L33: 9137.5 | M33: 5.039989 | O33: 8817 | P33: 4.8632101 | R33: 10775 | S33: 5.9431881 | U33: 2.7179 | V33: 106.99972 | W33: 106 | X33: 99.05
B34: ABR | C34: 10437.5 | D34: 4.7079387 | L34: 10537.5 | M34: 4.7530447 | O34: 9523.8 | P34: 4.2958051 | R34: 12562.5 | S34: 5.6664411 | U34: 2.2912 | V34: 90.201173 | W34: 96 | X34: 94.44
B35: MAI | C35: 12462.5 | D35: 4.7932692 | L35: 13400 | M35: 5.1538462 | O35: 11389.8 | P35: 4.3806923 | R35: 14675 | S35: 5.6442308 | U35: 2.5863 | V35: 101.81883 | W35: 100 | X35: 94.07
B36: JUN | C36: 14812.5 | D36: 4.3566176 | L36: 17000 | M36: 5 | O36: 15274.8 | P36: 4.4925882 | R36: 17062.5 | S36: 5.0183824 | U36: 2.5565 | V36: 100.64564 | W36: 108 | X36: 83.64
B37: JUL | C37: 19650 | D37: 5.1038961 | L37: 21320 | M37: 5.5376623 | O37: 18627 | P37: 4.8381818 | R37: 22000 | S37: 5.7142857 | U37: 2.3288 | V37: 91.68143 | W37: 105 | X37: 95.24
B38: AGO | C38: 27937.5 | D38: 6.0080645 | L38: 27875 | M38: 5.9946237 | O38: 23460 | P38: 5.0451613 | R38: 32625 | S38: 7.016129 | U38: 2.193 | V38: 86.335184 | W38: 102 | X38: 116.94
B39: SET | C39: 37700 | D39: 6.5474123 | L39: 39400 | M39: 6.8426537 | O39: 31980 | P39: 5.5540118 | R39: 44300 | S39: 7.6936436 | U39: 2.1839 | V39: 85.97693 | W39: 102 | X39: 128.23
B40: OUT | C40: 48250 | D40: 6.5645365 | L40: 51000 | M40: 6.9386811 | O40: 43080 | P40: 5.8611447 | R40: 56875 | S40: 7.73799 | U40: 2.0889 | V40: 82.23692 | W40: 103 | X40: 128.97
B41: NOV | C41: 63250 | D41: 7.1289294 | L41: 64875 | M41: 7.3120837 | O41: 53340 | P41: 6.0119698 | R41: 74125 | S41: 8.3546544 | U41: 2.1195 | V41: 83.441597 | W41: 114 | X41: 139.24
B42: DEZ | C42: 81700 | D42: 7.3911234 | L42: 82100 | M42: 7.4273101 | O42: 72840 | P42: 6.5895891 | R42: 100900 | S42: 9.1280827 | U42: 2.1999 | V42: 86.606827 | W42: 118 | X42: 152.13
A43: 1993 | B43: JAN | C43: 96250 | D43: 6.846051 | L43: 101125 | M43: 7.192799 | O43: 83880 | P43: 5.9662001 | R43: 115500 | S43: 8.2152612 | U43: 2.1771 | V43: 85.709224 | W43: 118 | X43: 136.92
...

Sheet Milho Charts

Sheet Soja
C4: Soja | D4: Soja | E4: Soja | F4: Soja | G4: Soja | H4: Soja | I4: Soja | J4: Soja | K4: Soja | L4: Soja | M4: Soja | N4: Soja | O4: Soja | P4: Soja | Q4: Farelo de soja | R4: Farelo de soja | S4: Farelo de soja | T4: Farelo de soja | U4: Óleo de soja | V4: Óleo de soja | W4: Óleo de soja | X4: Óleo de soja
A5: Ano | B5: Mês | C5: PR | D5: PR | E5: PR | F5: Paranaguá | G5: RS | H5: RS | I5: RS | J5: MT | K5: MT | L5: MT | M5: CBOT | N5: CBOT | O5: CBOT | P5: Prêmio PR | Q5: Atacado SP | R5: Atacado SP | S5: Atacado SP | T5: CBOT | U5: Atacado SP | V5: Atacado SP | W5: Atacado SP | X5: CBOT
C6: R$/60 kg | D6: US$/60 kg | E6: Deflacionado | F6: R$/60 kg | G6: R$/60 kg | H6: US$/60 kg | I6: Deflacionado | J6: R$/60 kg | K6: US$/60 kg | L6: Deflacionado | M6: US$/t | N6: US$/60kg | O6: US$/bushel | P6: US$/bushel | Q6: R$/t | R6: US$/t | S6: Deflacionado | T6: US$/t | U6: R$/t | V6: US$/t | W6: Deflacionado | X6: US$/t
A7: 1990 | B7: JAN | C7: 169.4 | D7: 11.834568 | G7: 165 | H7: 11.527176 | J7: 123.67296 | K7: 8.64 | M7: 207.5 | N7: 12.449794 | O7: 5.6472266 | Q7: 3964 | R7: 276.93168 | T7: 191.31
B8: FEV | C8: 258.75 | D8: 10.935717 | G8: 251.25 | H8: 10.61874 | J8: 199.22562 | K8: 8.42 | M8: 204.1 | N8: 12.245797 | O8: 5.5546937 | Q8: 5325 | R8: 225.05389 | T8: 182.28
B9: MAR | C9: 377.5 | D9: 10.00106 | G9: 365 | H9: 9.6698988 | J9: 283.84992 | K9: 7.52 | M9: 207.5 | N9: 12.449794 | O9: 5.6472266 | Q9: 7850 | R9: 207.96906 | T9: 184.33
B10: ABR | C10: 455 | D10: 9.5156433 | G10: 422.5 | H10: 8.8359545 | J10: 353.8384 | K10: 7.4 | M10: 213.7 | N10: 12.821788 | O10: 5.815963 | Q10: 7750 | R10: 162.07964 | T10: 191.07
B11: MAI | C11: 524 | D11: 10.037737 | G11: 510 | H11: 9.7695535 | J11: 461.47452 | K11: 8.84 | M11: 219.2 | N11: 13.151782 | O11: 5.9656485 | Q11: 9360 | R11: 179.30004 | T11: 200.11
B12: JUN | C12: 538.75 | D12: 9.4234839 | G12: 527.5 | H12: 9.2267058 | J12: 456.79629 | K12: 7.99 | M12: 215.9 | N12: 12.953786 | O12: 5.8758372 | Q12: 9250 | R12: 161.79532 | T12: 192.49
B13: JUL | C13: 615.75 | D13: 9.2436912 | G13: 605 | H13: 9.0823113 | J13: 494.93459 | K13: 7.43 | M13: 219.2 | N13: 13.151782 | O13: 5.9656485 | Q13: 10875 | R13: 163.25642 | T13: 193.98
B14: AGO | C14: 687 | D14: 9.5759806 | G14: 678 | H14: 9.4505311 | J14: 515.82498 | K14: 7.19 | M14: 220.3 | N14: 13.217781 | O14: 5.9955856 | Q14: 11820 | R14: 164.75705 | T14: 192.7
B15: SET | C15: 732.5 | D15: 9.6632059 | G15: 725 | H15: 9.5642653 | J15: 585.95719 | K15: 7.73 | M15: 219.9 | N15: 13.193782 | O15: 5.9846994 | Q15: 13000 | R15: 171.49717 | T15: 198.23
B16: OUT | C16: 950 | D16: 9.9535849 | G16: 944 | H16: 9.8907201 | J16: 640.42253 | K16: 6.71 | M16: 215.5 | N16: 12.929786 | O16: 5.864951 | Q16: 16720 | R16: 175.18309 | T16: 200.77
B17: NOV | C17: 1180 | D17: 9.6816541 | G17: 1171.5 | H17: 9.6119134 | J17: 828.784 | K17: 6.8 | M17: 212.2 | N17: 12.731789 | O17: 5.7751397 | Q17: 23250 | R17: 190.7614 | T17: 192.07
B18: DEZ | C18: 1517.5 | D18: 9.7578384 | G18: 1527.5 | H18: 9.8221405 | J18: 1297.0034 | K18: 8.34 | M18: 210 | N18: 12.599792 | O18: 5.7152655 | Q18: 29000 | R18: 186.47599 | T18: 190.03
A19: 1991 | B19: JAN | C19: 1869 | D19: 8.4900518 | G19: 1847 | H19: 8.3901154 | J19: 1662.057 | K19: 7.55 | M19: 210 | N19: 12.599792 | O19: 5.7152655 | Q19: 36200 | R19: 164.44081 | T19: 180.41
B20: FEV | C20: 2260 | D20: 10.115025 | G20: 2292.5 | H20: 10.260484 | J20: 2004.1671 | K20: 8.97 | M20: 207.5 | N20: 12.449794 | O20: 5.6472266 | Q20: 39937.5 | R20: 178.74726 | T20: 183.56
B21: MAR | C21: 2330 | D21: 9.7518102 | G21: 2392.5 | H21: 10.013393 | J21: 2147.9807 | K21: 8.99 | M21: 211.9 | N21: 12.71379 | O21: 5.766975 | Q21: 36625 | R21: 153.28757 | T21: 184.08
B22: ABR | C22: 2525 | D22: 9.6843478 | G22: 2600 | H22: 9.9720017 | J22: 2247.4926 | K22: 8.62 | M22: 211.9 | N22: 12.71379 | O22: 5.766975 | Q22: 38625 | R22: 148.14176 | T22: 190.39
B23: MAI | C23: 2686 | D23: 9.4344924 | G23: 2735 | H23: 9.6066034 | J23: 2371.551 | K23: 8.33 | M23: 205.2 | N23: 12.311796 | O23: 5.5846308 | Q23: 41050 | R23: 144.18686 | T23: 189.54
B24: JUN | C24: 2992.5 | D24: 9.5842808 | G24: 3055 | H24: 9.7844538 | J24: 2516.5738 | K24: 8.06 | M24: 203.8 | N24: 12.227798 | O24: 5.5465291 | Q24: 46125 | R24: 147.72764 | T24: 190.08
B25: JUL | C25: 3208 | D25: 9.2564273 | G25: 3246 | H25: 9.3660732 | J25: 2755.2315 | K25: 7.95 | M25: 233.5 | N25: 14.009768 | O25: 6.3548309 | Q25: 52300 | R25: 150.90746 | T25: 184.7
B26: AGO | C26: 3910 | D26: 10.426667 | G26: 3985 | H26: 10.626667 | J26: 2876.25 | K26: 7.67 | M26: 207.8 | N26: 12.467794 | O26: 5.6553913 | Q26: 68875 | R26: 183.66667 | T26: 199.18
B27: SET | C27: 4982.5 | D27: 11.323864 | G27: 5190 | H27: 11.795455 | J27: 3832.4 | K27: 8.71 | M27: 207.1 | N27: 12.425794 | O27: 5.6363404 | Q27: 82875 | R27: 188.35227 | T27: 213.29
B28: OUT | C28: 7040.6 | D28: 11.734333 | G28: 7180 | H28: 11.966667 | J28: 6060 | K28: 10.1 | M28: 201.6 | N28: 12.0958 | O28: 5.4866549 | Q28: 122200 | R28: 203.66667 | T28: 203.29
B29: NOV | C29: 7840 | D29: 10.384106 | G29: 8055 | H29: 10.668874 | J29: 6296.7 | K29: 8.34 | M29: 201.2 | N29: 12.0718 | O29: 5.4757686 | Q29: 140250 | R29: 185.76159 | T29: 198.68
B30: DEZ | C30: 9517.5 | D30: 9.7315951 | G30: 10092.5 | H30: 10.31953 | J30: 7462.14 | K30: 7.63 | M30: 200.1 | N30: 12.005801 | O30: 5.4458315 | Q30: 193750 | R30: 198.10838 | T30: 191.3
A31: 1992 | B31: JAN | C31: 12944 | D31: 10.813701 | G31: 12840 | H31: 10.726817 | J31: 8312.4 | K31: 6.9443609 | M31: 203.4 | N31: 12.203798 | O31: 5.5356428 | Q31: 276800 | R31: 231.24478 | T31: 193.29
B32: FEV | C32: 14938.75 | D32: 10.134837 | G32: 15230 | H32: 10.332429 | J32: 13601.52 | K32: 9.2276255 | M32: 205.2 | N32: 12.311796 | O32: 5.5846308 | Q32: 302250 | R32: 205.05427 | T32: 192.7
B33: MAR | C33: 18530 | D33: 10.220629 | G33: 16890 | H33: 9.3160507 | J33: 15282.29 | K33: 8.429283 | M33: 208.2 | N33: 12.491793 | O33: 5.6662775 | Q33: 323500 | R33: 178.43354 | T33: 194.95
B34: ABR | C34: 20850 | D34: 9.4046008 | G34: 20700 | H34: 9.3369418 | J34: 17197.8 | K34: 7.7572395 | M34: 207.8 | N34: 12.467794 | O34: 5.6553913 | Q34: 350000 | R34: 157.871 | T34: 192.53
B35: MAI | C35: 26025 | D35: 10.009615 | G35: 24900 | H35: 9.5769231 | J35: 21598.3 | K35: 8.3070385 | M35: 215.5 | N35: 12.929786 | O35: 5.864951 | Q35: 406525 | R35: 156.35577 | T35: 200.11
B36: JUN | C36: 33337.5 | D36: 9.8051471 | G36: 32050 | H36: 9.4264706 | J36: 29657.3 | K36: 8.7227353 | M36: 218.1 | N36: 13.085784 | O36: 5.9357114 | Q36: 530500 | R36: 156.02941 | T36: 201.31
B37: JUL | C37: 39420 | D37: 10.238961 | G37: 38680 | H37: 10.046753 | J37: 35291.64 | K37: 9.1666597 | M37: 205.2 | N37: 12.311796 | O37: 5.5846308 | Q37: 700600 | R37: 181.97403 | T37: 192.68
B38: AGO | C38: 52325 | D38: 11.252688 | G38: 50837.5 | H38: 10.932796 | J38: 46713.92 | K38: 10.046004 | M38: 198.3 | N38: 11.897803 | O38: 5.3968435 | Q38: 926925 | R38: 199.33871 | T38: 210.19
B39: SET | C39: 71940 | D39: 12.493922 | G39: 71220 | H39: 12.368878 | J39: 64569.89 | K39: 11.213944 | M39: 196.4 | N39: 11.783805 | O39: 5.345134 | Q39: 1313400 | R39: 228.10003 | T39: 195.46
B40: OUT | C40: 85962.5 | D40: 11.695419 | G40: 87487.5 | H40: 11.902899 | J40: 78555.4 | K40: 10.687664 | M40: 193.1 | N40: 11.585808 | O40: 5.2553227 | Q40: 1517400 | R40: 206.44617 | T40: 199.87
B41: NOV | C41: 106900 | D41: 12.048736 | G41: 104587.5 | H41: 11.788093 | J41: 98044.21 | K41: 11.050597 | M41: 196.8 | N41: 11.807805 | O41: 5.3560202 | Q41: 1775591.5 | R41: 200.12753 | T41: 199.13
B42: DEZ | C42: 138212 | D42: 12.503573 | G42: 142468 | H42: 12.888599 | J42: 117011.36 | K42: 10.585623 | M42: 200.5 | N42: 12.029801 | O42: 5.4567178 | Q42: 2278340 | R42: 206.11373 | T42: 204.67
A43: 1993 | B43: JAN | C43: 173262.5 | D43: 12.323781 | G43: 177912.5 | H43: 12.654525 | J43: 149186.72 | K43: 10.611324 | M43: 204.09 | N43: 12.245197 | O43: 5.5544216 | Q43: 2945890.5 | R43: 209.53472 | T43: 203.32
...

Sheet Soja Charts

Sheet Trigo
C4: Trigo | D4: Trigo | E4: Trigo | F4: Trigo | G4: Trigo | H4: Trigo | I4: Trigo | J4: Trigo | K4: Trigo | L4: Trigo
A5: Ano | B5: Mês | C5: PR | D5: PR | E5: PR | F5: PR | G5: RS | H5: RS | I5: RS | J5: Argentina FOB | K5: US SRW | L5: US HRW
C6: R$/60 kg | D6: US$/60 kg | E6: Deflacionado | F6: US$/t | G6: R$/60 kg | H6: US$/60 kg | I6: Deflacionado | J6: US$/t | K6: US$/t | L6: US$/t
A7: 1990 | B7: JAN | C7: 92.89786 | D7: 6.49 | G7: 136.98498 | H7: 9.57 | K7: 163 | L7: 167.92
B8: FEV | C8: 154.26972 | D8: 6.52 | G8: 157.81887 | H8: 6.67 | K8: 155.52 | L8: 160.94
B9: MAR | C9: 245.72646 | D9: 6.51 | G9: 269.50644 | H9: 7.14 | K9: 153.26 | L9: 156.53
B10: ABR | C10: 394.482 | D10: 8.25 | G10: 315.10744 | H10: 6.59 | K10: 150.69 | L10: 159.47
B11: MAI | C11: 448.42377 | D11: 8.59 | G11: 444.24753 | H11: 8.51 | K11: 133.49 | L11: 149.18
B12: JUN | C12: 461.36997 | D12: 8.07 | G12: 451.6509 | H12: 7.9 | K12: 130.49 | L12: 135.58
B13: JUL | C13: 503.59428 | D13: 7.56 | G13: 506.2588 | H13: 7.6 | K13: 119.55 | L13: 124.93
B14: AGO | C14: 566.7618 | D14: 7.9 | G14: 545.2392 | H14: 7.6 | K14: 115.12 | L14: 116.84
B15: SET | C15: 606.424 | D15: 8 | G15: 553.3619 | H15: 7.3 | K15: 108.46 | L15: 114.27
B16: OUT | C16: 733.95667 | D16: 7.69 | G16: 805.53892 | H16: 8.44 | K16: 104.77 | L16: 114.64
B17: NOV | C17: 823.9088 | D17: 6.76 | G17: 893.3804 | H17: 7.33 | K17: 106.37 | L17: 112.8
B18: DEZ | C18: 1049.733 | D18: 6.75 | G18: 1097.943 | H18: 7.06 | K18: 108.35 | L18: 113.17
A19: 1991 | B19: JAN | C19: 1413.2988 | D19: 6.42 | G19: 1523.3688 | H19: 6.92 | K19: 107.07 | L19: 111.33
B20: FEV | C20: 1503.6839 | D20: 6.73 | G20: 1539.4327 | H20: 6.89 | K20: 106.37 | L20: 113.91
B21: MAR | C21: 1651.0063 | D21: 6.91 | G21: 1739.4104 | H21: 7.28 | K21: 116.16 | L21: 119.42
B22: ABR | C22: 1749.4983 | D22: 6.71 | G22: 1726.0326 | H22: 6.62 | K22: 117.05 | L22: 120.89
B23: MAI | C23: 1839.162 | D23: 6.46 | G23: 1861.938 | H23: 6.54 | K23: 115.63 | L23: 121.99
B24: JUN | C24: 1973.2936 | D24: 6.32 | G24: 1985.7828 | H24: 6.36 | K24: 118.18 | L24: 120.15
B25: JUL | C25: 2231.9108 | D25: 6.44 | G25: 2100.2142 | H25: 6.06 | K25: 116.23 | L25: 118.31
B26: AGO | C26: 2306.25 | D26: 6.15 | G26: 2538.75 | H26: 6.77 | K26: 127.06 | L26: 125.3
B27: SET | C27: 2882 | D27: 6.55 | G27: 3018.4 | H27: 6.86 | K27: 137.56 | L27: 135.22
B28: OUT | C28: 3318 | D28: 5.53 | G28: 3714 | H28: 6.19 | K28: 147.2 | L28: 146.97
B29: NOV | C29: 4288.4 | D29: 5.68 | G29: 4431.85 | H29: 5.87 | K29: 147.04 | L29: 149.55
B30: DEZ | C30: 5476.8 | D30: 5.6 | G30: 5750.64 | H30: 5.88 | K30: 157.81 | L30: 160.94
A31: 1992 | B31: JAN | C31: 6439.86 | D31: 5.38 | G31: 7146.09 | H31: 5.97 | K31: 167.26 | L31: 170.12
B32: FEV | C32: 7517.4 | D32: 5.1 | G32: 8195.44 | H32: 5.56 | K32: 170.12 | L32: 177.1
B33: MAR | C33: 11965.8 | D33: 6.6 | G33: 11458.16 | H33: 6.32 | K33: 161.44 | L33: 169.39
B34: ABR | C34: 16472.31 | D34: 7.43 | G34: 14809.56 | H34: 6.68 | K34: 153.07 | L34: 159.83
B35: MAI | C35: 20176 | D35: 7.76 | G35: 19058 | H35: 7.33 | K35: 139.72 | L35: 149.55
B36: JUN | C36: 27744 | D36: 8.16 | G36: 25908 | H36: 7.62 | K36: 140.36 | L36: 148.81
B37: JUL | C37: 30877 | D37: 8.02 | G37: 29606.5 | H37: 7.69 | K37: 129.93 | L37: 136.32
B38: AGO | C38: 36363 | D38: 7.82 | G38: 35944.5 | H38: 7.73 | K38: 118.8 | L38: 128.24
B39: SET | C39: 45200.3 | D39: 7.85 | G39: 44221.44 | H39: 7.68 | K39: 131.47 | L39: 138.89
B40: OUT | C40: 57624.784 | D40: 7.84 | G40: 55860.76 | H40: 7.6 | K40: 137.42 | L40: 140.73
B41: NOV | C41: 68937.771 | D41: 7.77 | G41: 70091.17 | H41: 7.9 | K41: 145.84 | L41: 147.71
B42: DEZ | C42: 89867.394 | D42: 8.13 | G42: 86551.254 | H42: 7.83 | K42: 146.27 | L42: 147.71
A43: 1993 | B43: JAN | C43: 104038.08 | D43: 7.4 | G43: 109380.58 | H43: 7.78 | K43: 156.92 | L43: 155.79
...

Sheet Trigo Charts

Sheet Cana
C4: Acúcar | D4: Acúcar | E4: Acúcar | F4: Acúcar | G4: Cana | H4: Cana | I4: Cana | J4: Etanol Anidro | K4: Etanol Anidro | L4: Etanol Anidro | M4: Etanol Hidratado Hidratado | N4: Etanol Hidratado Hidratado | O4: Etanol Hidratado Hidratado
A5: Ano | B5: Mês | C5: Atacado SP | D5: Atacado SP | E5: Atacado SP | F5: Futuros ICE NY | G5: SP | H5: SP | I5: SP | J5: FOB usina SP | K5: FOB usina SP | L5: FOB usina SP | M5: FOB usina SP | N5: FOB usina SP | O5: FOB usina SP
C6: R$/50 kg | D6: US$/50 kg | E6: Deflacionado | F6: ¢/libra-peso | G6: R$/t | H6: US$/t | I6: Deflacionado | J6: R$/litro | K6: US$/litro | L6: Deflacionado | M6: R$/litro | N6: US$/litro | O6: Deflacionado
A7: 1990 | B7: JAN | G7: 162.19
B8: FEV | G8: 255.93
B9: MAR | G9: 387.18
B10: ABR | G10: 568.28
B11: MAI | G11: 567.23
B12: JUN | G12: 567.7
B13: JUL | G13: 569.62
B14: AGO | G14: 709.9
B15: SET | G15: 830.69
B16: OUT | G16: 981.53
B17: NOV | G17: 1291.62
B18: DEZ | G18: 1435.77
A19: 1991 | B19: JAN | G19: 1651.55
B20: FEV | G20: 2493.88
B21: MAR | G21: 2472.33
B22: ABR | G22: 2564.27
B23: MAI | G23: 2578.11
B24: JUN | G24: 2715.66
B25: JUL | G25: 3090.94
B26: AGO | G26: 3382.72
B27: SET | G27: 3757.82
B28: OUT | G28: 5324.49
B29: NOV | G29: 6382.79
B30: DEZ | G30: 8719.44
A31: 1992 | B31: JAN | G31: 10889.19
B32: FEV | G32: 13605.17
B33: MAR | G33: 17518.8
B34: ABR | G34: 19664.79
B35: MAI | G35: 24333.63
B36: JUN | G36: 30355.81
B37: JUL | G37: 38876.64
B38: AGO | G38: 48269.66
B39: SET | G39: 60105
B40: OUT | G40: 75052
B41: NOV | G41: 78850
B42: DEZ | G42: 95668
A43: 1993 | B43: JAN | G43: 106484
...

Sheet Cana Charts
B35: PREÇOS FOB USINAS - SÃO PAULO
B36: ANO-SAFRA | C36: ETANOL ANIDRO | E36: ETANOL HIDRATADO
C37: R$/LITRO | D37: US$/LITRO | E37: R$/LITRO | F37: US$/LITRO
B38: MÉDIA 2020/2021 | C38: =AVERAGE(Cana!J370:J381) -> 2.1749083 | D38: =AVERAGE(Cana!K370:K381) -> 0.40191807 | E38: =AVERAGE(Cana!M370:M381) -> 1.9054083 | F38: =AVERAGE(Cana!N370:N381) -> 0.35201233
B39: MÉDIA 2021/2022 | C39: =AVERAGE(Cana!J382:J393) -> 3.6412 | D39: =AVERAGE(Cana!K382:K393) -> 0.68268734 | E39: =AVERAGE(Cana!M382:M393) -> 3.15505 | F39: =AVERAGE(Cana!N382:N393) -> 0.59153672
B40: MÉDIA 2022/2023 | C40: =AVERAGE(Cana!J394:J405) -> 3.3288333 | D40: =AVERAGE(Cana!K394:K405) -> 0.64827058 | E40: =AVERAGE(Cana!M394:M405) -> 2.8881083 | F40: =AVERAGE(Cana!N394:N405) -> 0.56276154
B41: MÉDIA 2023/2024 | C41: =AVERAGE(Cana!J406:J416) -> 2.6098 | D41: =AVERAGE(Cana!K406:K416) -> 0.52939763 | E41: =AVERAGE(Cana!M406:M416) -> 2.2690909 | F41: =AVERAGE(Cana!N406:N416) -> 0.46012882
B42: MÉDIA 2024/2025 | C42: =AVERAGE(Cana!J417:J429) -> 2.8921231 | D42: =AVERAGE(Cana!K417:K429) -> 0.51420544 | E42: =AVERAGE(Cana!M417:M429) -> 2.5525385 | F42: =AVERAGE(Cana!N417:N429) -> 0.45377963
B43: MÉDIA 2025/2026 | C43: =AVERAGE(Cana!J430:J441) -> 3.19395 | D43: =AVERAGE(Cana!K430:K441) -> 0.58835357 | E43: =AVERAGE(Cana!M430:M441) -> 2.793725 | F43: =AVERAGE(Cana!N430:N441) -> 0.51472102
B44: MÉDIA 2026/2027 | C44: =AVERAGE(Cana!J442:J443) -> 2.785 | D44: =AVERAGE(Cana!K442:K443) -> 0.5565773 | E44: =AVERAGE(Cana!M442:M443) -> 2.4246 | F44: =AVERAGE(Cana!N442:N443) -> 0.48454495
B45: VAR. 30 DIAS (%) | C45: 0 | D45: -0.0076923077 | E45: 0.14419924 | F45: 0.13539771
B46: VAR. 12 MESES (%) | C46: -0.20496894 | D46: -0.18356426 | E46: -0.061090909 | F46: -0.035812587
B49: ETHANOL AVERAGE PRICES - FOB SÃO PAULO PLANTS
B50: HARVEST | C50: ANHYDROUS ETHANOL | E50: HYDROUS ETHANOL
C51: R$/l | D51: U$/l | E51: R$/l | F51: U$/l
B52: 2019/2020 | C52: =#REF! -> #REF! | D52: =#REF! -> #REF! | E52: =#REF! -> #REF! | F52: =#REF! -> #REF!
B53: 2020/2021 | C53: =C38 -> 2.1749083 | D53: =D38 -> 0.40191807 | E53: =E38 -> 1.9054083 | F53: =F38 -> 0.35201233
B54: 2021/2022 | C54: =C39 -> 3.6412 | D54: =D39 -> 0.68268734 | E54: =E39 -> 3.15505 | F54: =F39 -> 0.59153672
B55: 2022/2023 | C55: =C40 -> 3.3288333 | D55: =D40 -> 0.64827058 | E55: =E40 -> 2.8881083 | F55: =F40 -> 0.56276154
B56: 2023/2024 | C56: =C41 -> 2.6098 | D56: =D41 -> 0.52939763 | E56: =E41 -> 2.2690909 | F56: =F41 -> 0.46012882
B57: 2024/2025 | C57: =C42 -> 2.8921231 | D57: =D42 -> 0.51420544 | E57: =E42 -> 2.5525385 | F57: =F42 -> 0.45377963
B58: 2025/2026 | C58: =C43 -> 3.19395 | D58: =D43 -> 0.58835357 | E58: =E43 -> 2.793725 | F58: =F43 -> 0.51472102
B59: 30 DAYS CHANGE | C59: =C45 -> 0 | D59: =D45 -> -0.0076923077 | E59: =E45 -> 0.14419924 | F59: =F45 -> 0.13539771
B60: 12 MO CHANGE | C60: =C46 -> -0.20496894 | D60: =D46 -> -0.18356426 | E60: =E46 -> -0.061090909 | F60: =F46 -> -0.035812587

Sheet Demais AGRÍCOLAS
C4: Café Arábica | D4: Café Arábica | E4: Café Arábica | F4: Café Arábica | G4: Café Robusta | H4: Café Robusta | I4: Café Robusta | J4: Feijão | K4: Feijão | L4: Feijão | M4: Laranja | N4: Laranja | O4: Laranja | P4: Laranja | Q4: Laranja | R4: Laranja
A5: Ano | B5: Mês | C5: SP | D5: SP | E5: SP | F5: Futuros ICE NY | G5: ES | H5: ES | I5: ES | J5: Cores SP | K5: Cores SP | L5: Cores SP | M5: Indústria SP | N5: Indústria SP | O5: Indústria SP | P5: Mesa SP | Q5: Mesa SP | R5: Mesa SP
C6: R$/60 kg | D6: US$/60 kg | E6: Deflacionado | F6: ¢/libra-peso | G6: R$/60 kg | H6: US$/60 kg | I6: Deflacionado | J6: R$/60 kg | K6: US$/60 kg | L6: Deflacionado | M6: R$/40,8 kg | N6: US$/40,8 kg | O6: Deflacionado | P6: R$/40,8 kg | Q6: US$/40,8 kg | R6: Deflacionado
A7: 1990 | B7: JAN | C7: 1381.301 | D7: 96.5 | F7: 80.65 | J7: 404.15 | K7: 28.234596
B8: FEV | C8: 2247.795 | D8: 95 | F8: 85.64 | J8: 538.95 | K8: 22.777989
B9: MAR | C9: 3170.664 | D9: 84 | F9: 94.64 | J9: 1121.26 | K9: 29.705399
B10: ABR | C10: 4030.8888 | D10: 84.3 | F10: 94.83 | J10: 1201.28 | K10: 25.122971
B11: MAI | C11: 4218.0024 | D11: 80.8 | F11: 94.39 | J11: 1596.4 | K11: 30.580618
B12: JUN | C12: 4236.3711 | D12: 74.1 | F12: 89.13 | J12: 1960.21 | K12: 34.286789
B13: JUL | C13: 4323.1837 | D13: 64.9 | F13: 87.7 | J13: 2222.48 | K13: 33.364058
B14: AGO | C14: 5775.231 | D14: 80.5 | F14: 95.07 | J14: 2312.11 | K14: 32.228123
B15: SET | C15: 5942.9552 | D15: 78.4 | F15: 97.05 | J15: 2322.75 | K15: 30.641927
B16: OUT | C16: 5965.1875 | D16: 62.5 | F16: 92.41 | J16: 2773.65 | K16: 29.060801
B17: NOV | C17: 6179.316 | D17: 50.7 | F17: 84.58 | J17: 3267.58 | K17: 26.809813
B18: DEZ | C18: 7977.9708 | D18: 51.3 | F18: 91.4 | J18: 3307 | K18: 21.264693
A19: 1991 | B19: JAN | C19: 11799.504 | D19: 53.6 | F19: 87.05 | J19: 4293.31 | K19: 19.502635
B20: FEV | C20: 14187.805 | D20: 63.5 | F20: 88.22 | J20: 5292.44 | K20: 23.68724
B21: MAR | C21: 16103.882 | D21: 67.4 | F21: 93.54 | J21: 5967.77 | K21: 24.977064
B22: ABR | C22: 17077.815 | D22: 65.5 | F22: 90.91 | J22: 8359 | K22: 32.059985
B23: MAI | C23: 16968.12 | D23: 59.6 | F23: 88.08 | J23: 10422.6 | K23: 36.609062
B24: JUN | C24: 18015.671 | D24: 57.7 | F24: 85.35 | J24: 11254.8 | K24: 36.046504
B25: JUL | C25: 18922.722 | D25: 54.6 | F25: 83.68 | J25: 11682 | K25: 33.707476
B26: AGO | C26: 19125 | D26: 51 | F26: 81.52 | J26: 9857.4 | K26: 26.2864
B27: SET | C27: 25432 | D27: 57.8 | F27: 89.88 | J27: 10122.6 | K27: 23.005909
B28: OUT | C28: 30720 | D28: 51.2 | F28: 81.56 | J28: 13957.2 | K28: 23.262
B29: NOV | C29: 36844 | D29: 48.8 | F29: 78.57 | J29: 14869.2 | K29: 19.694305
B30: DEZ | C30: 44205.6 | D30: 45.2 | F30: 79.7 | J30: 16318.8 | K30: 16.68589
A31: 1992 | B31: JAN | C31: 55421.1 | D31: 46.3 | F31: 77.38 | J31: 22853.4 | K31: 19.092231
B32: FEV | C32: 66035.2 | D32: 44.8 | F32: 68.81 | J32: 28166.4 | K32: 19.10882
B33: MAR | C33: 84123.2 | D33: 46.4 | F33: 71.86 | J33: 35218.8 | K33: 19.425703
B34: ABR | C34: 101095.2 | D34: 45.6 | F34: 66.43 | J34: 41796.6 | K34: 18.852774
B35: MAI | C35: 109200 | D35: 42 | F35: 63.02 | J35: 49600.8 | K35: 19.077231
B36: JUN | C36: 137360 | D36: 40.4 | F36: 59.64 | J36: 54648 | K36: 16.072941
B37: JUL | C37: 154000 | D37: 40 | F37: 60.16 | J37: 69353.4 | K37: 18.01387
B38: AGO | C38: 182280 | D38: 39.2 | F38: 52.5 | J38: 99448.8 | K38: 21.386839
B39: SET | C39: 238957 | D39: 41.5 | F39: 54.16 | J39: 151363.8 | K39: 26.287565
B40: OUT | C40: 378530.15 | D40: 51.5 | F40: 63.16 | J40: 197884.2 | K40: 26.922654
B41: NOV | C41: 528789.08 | D41: 59.6 | F41: 67.8 | J41: 259608 | K41: 29.260507
B42: DEZ | C42: 822402.72 | D42: 74.4 | F42: 78.37 | J42: 270187.2 | K42: 24.442925
A43: 1993 | B43: JAN | C43: 970084.8 | D43: 69 | F43: 66.55 | J43: 292074 | K43: 20.774582
...

Sheet Demais AGRÍCOLAS Charts

Sheet PECUÁRIA
C4: Bezerro | D4: Bezerro | E4: Bezerro | F4: Boi Gordo | G4: Boi Gordo | H4: Boi Gordo | I4: Beef | J4: Frango vivo | K4: Frango vivo | L4: Frango vivo | M4: Frango vivo | N4: Frango Resfriado | O4: Frango Resfriado | P4: Frango Resfriado | Q4: Chicken Meat | R4: Suíno vivo | S4: Suíno vivo | T4: Suíno vivo | U4: Suíno vivo | V4: Suíno Carcaça | W4: Suíno Carcaça | X4: Suíno Carcaça | Y4: Ovos Brancos | Z4: Ovos Brancos | AA4: Ovos Brancos | AB4: Tilápia | AC4: Tilápia | AD4: Tilápia
A5: Ano | B5: Mês | C5: MS | D5: MS | E5: MS | F5: SP | G5: SP | H5: SP | J5: SP | K5: SP | L5: SP | M5: Custo Produção | N5: Atacado SP | O5: Atacado SP | P5: Atacado SP | R5: SC | S5: SC | T5: SC | U5: Custo Produção | V5: SP | W5: SP | X5: SP | Y5: Atacado SP | Z5: Atacado SP | AA5: Atacado SP | AB5: Norte PR | AC5: Norte PR | AD5: Norte PR
C6: R$/un | D6: US$/un | E6: Deflacionado | F6: R$/@ | G6: Deflacionado | H6: US$/@ | I6: US$/kg | J6: R$/kg | K6: US$/kg | L6: Deflacionado | M6: R$/kg | N6: R$/kg | O6: US$/kg | P6: Deflacionado | Q6: US$/kg | R6: R$/kg | S6: US$/kg | T6: Deflacionado | U6: R$/kg | V6: R$/kg | W6: US$/kg | X6: Deflacionado | Y6: R$/cx. 30 dz. | Z6: US$/cx. 30 dz. | AA6: Deflacionado | AB6: R$/kg | AC6: US$/kg | AD6: Deflacionado
A7: 1990 | B7: JAN | F7: 0 | I7: 2.7847 | J7: 11.88062 | K7: 0.83 | Q7: 1.0544697 | R7: 12.816703 | S7: 0.89539631
B8: FEV | F8: 0 | I8: 2.4573 | J8: 20.58507 | K8: 0.87 | Q8: 1.0714453 | R8: 20.65199 | S8: 0.8728283
B9: MAR | F9: 0 | I9: 2.4839 | J9: 42.27552 | K9: 1.12 | Q9: 1.1098057 | R9: 36.27762 | S9: 0.9610984
B10: ABR | F10: 0 | I10: 2.472 | J10: 35.862 | K10: 0.75 | Q10: 1.081807 | R10: 32.963065 | S10: 0.68937313
B11: MAI | F11: 0 | I11: 2.48 | J11: 38.10819 | K11: 0.73 | Q11: 1.0809252 | R11: 50.659438 | S11: 0.97043154
B12: JUN | F12: 0 | I12: 2.504 | J12: 49.16706 | K12: 0.86 | Q12: 1.1082625 | R12: 57.630092 | S12: 1.0080302
B13: JUL | F13: 0 | I13: 2.5589 | J13: 57.95331 | K13: 0.87 | Q13: 1.1034123 | R13: 78.421624 | S13: 1.1772721
B14: AGO | F14: 0 | I14: 2.6541 | J14: 65.28522 | K14: 0.91 | Q14: 1.0961371 | R14: 81.09453 | S14: 1.1303634
B15: SET | F15: 0 | I15: 2.6969 | J15: 85.65739 | K15: 1.13 | Q15: 1.0930506 | R15: 86.084111 | S15: 1.1356293
B16: OUT | F16: 0 | I16: 2.5851 | J16: 88.76199 | K16: 0.93 | Q16: 1.0729886 | R16: 70.3 | S16: 0.73656528
B17: NOV | F17: 0 | I17: 2.5342 | J17: 80.4408 | K17: 0.66 | Q17: 1.0657133 | R17: 78.53 | S17: 0.64432228
B18: DEZ | F18: 0 | I18: 2.5477 | J18: 90.19928 | K18: 0.58 | Q18: 1.0471945 | R18: 83.531531 | S18: 0.537125
A19: 1991 | B19: JAN | F19: 0 | I19: 2.5931 | J19: 138.6882 | K19: 0.63 | Q19: 1.0513833 | R19: 118.72209 | S19: 0.53930266
B20: FEV | F20: 0 | I20: 2.7269 | J20: 185.4469 | K20: 0.83 | Q20: 1.0754136 | R20: 151.02857 | S20: 0.67595473
B21: MAR | F21: 0 | I21: 2.5918 | J21: 164.8617 | K21: 0.69 | Q21: 1.0696816 | R21: 201.43694 | S21: 0.84307933
B22: ABR | F22: 0 | I22: 2.6112 | J22: 153.8307 | K22: 0.59 | Q22: 1.056013 | R22: 210.0982 | S22: 0.80580755
B23: MAI | F23: 0 | I23: 2.6259 | J23: 179.361 | K23: 0.63 | Q23: 1.0648315 | R23: 221.57209 | S23: 0.77826516
B24: JUN | F24: 0 | I24: 2.7029 | J24: 196.7049 | K24: 0.63 | Q24: 1.0471945 | R24: 225.03252 | S24: 0.72072676
B25: JUL | F25: 0 | I25: 2.6874 | J25: 218.3391 | K25: 0.63 | Q25: 1.0714453 | R25: 252.14767 | S25: 0.72755192
B26: AGO | F26: 0 | I26: 2.6411 | J26: 225 | K26: 0.6 | Q26: 1.0471945 | R26: 274.44747 | S26: 0.73185993
B27: SET | F27: 0 | I27: 2.7448 | J27: 255.2 | K27: 0.58 | Q27: 1.0471945 | R27: 295.19748 | S27: 0.67090337
B28: OUT | F28: 0 | I28: 2.7198 | J28: 348 | K28: 0.58 | Q28: 1.061745 | R28: 340.71465 | S28: 0.56785775
B29: NOV | F29: 0 | I29: 2.7073 | J29: 460.55 | K29: 0.61 | Q29: 1.0392579 | R29: 472.79732 | S29: 0.62622162
B30: DEZ | F30: 0 | I30: 2.6081 | J30: 557.46 | K30: 0.57 | Q30: 1.0416829 | R30: 538.20402 | S30: 0.55031086
A31: 1992 | B31: JAN | F31: 0 | I31: 2.5715 | J31: 670.32 | K31: 0.56 | Q31: 1.0538084 | R31: 603 | S31: 0.5037594
B32: FEV | F32: 0 | I32: 2.5241 | J32: 869.66 | K32: 0.59 | Q32: 1.0255892 | R32: 844 | S32: 0.57259159
B33: MAR | F33: 0 | I33: 2.4493 | J33: 870.24 | K33: 0.48 | Q33: 1.0392579 | R33: 1015 | S33: 0.55984556
B34: ABR | F34: 0 | I34: 2.3847 | J34: 908.97 | K34: 0.41 | Q34: 1.0368328 | R34: 1125 | S34: 0.50744249
B35: MAI | F35: 0 | I35: 2.3766 | J35: 1378 | K35: 0.53 | Q35: 1.0377146 | R35: 1321 | S35: 0.50807692
B36: JUN | F36: 0 | I36: 2.3347 | J36: 1802 | K36: 0.53 | Q36: 1.0480763 | R36: 1805 | S36: 0.53088235
B37: JUL | F37: 0 | I37: 2.3457 | J37: 1848 | K37: 0.48 | Q37: 1.0648315 | R37: 2113 | S37: 0.54883117
B38: AGO | F38: 0 | I38: 2.4454 | J38: 2511 | K38: 0.54 | Q38: 1.0769569 | R38: 2698 | S38: 0.58021505
B39: SET | F39: 0 | I39: 2.4403 | J39: 3397.22 | K39: 0.59 | Q39: 1.0778387 | R39: 3583 | S39: 0.62226468
B40: OUT | F40: 0 | I40: 2.5003 | J40: 4483.561 | K40: 0.61 | Q40: 1.056013 | R40: 4288 | S40: 0.58339342
B41: NOV | F41: 0 | I41: 2.5406 | J41: 5323.38 | K41: 0.6 | Q41: 1.0866572 | R41: 5272 | S41: 0.59420894
B42: DEZ | F42: 0 | I42: 2.5417 | J42: 7406.046 | K42: 0.67 | Q42: 1.0857754 | R42: 9257 | S42: 0.83744956
A43: 1993 | B43: JAN | F43: 0 | I43: 2.3545 | J43: 8857.296 | K43: 0.63 | Q43: 1.1128922 | R43: 11504 | S43: 0.81825424
...

Sheet PECUÁRIA Charts
R18: CARNES: EVOLUÇÃO DOS PREÇOS PAGOS AOS CRIADORES
R19: PERÍODO | S19: BOI GORDO | T19: FRANGO VIVO | U19: SUÍNO VIVO
R20: ÚLTIMOS 30 DIAS | S20: 0.041509434 | T20: 0.0042194093 | U20: 0.10805085
R21: ACUMULADO 2026 | S21: 0.11245466 | T21: -0.13296903 | U21: -0.37214886
R22: ÚLTIMOS 12 MESES | S22: 0.1737765 | T22: -0.13924051 | U22: -0.36759371

Sheet Leite
C4: LEITE | D4: LEITE | E4: LEITE | F4: LEITE | G4: LEITE | H4: LEITE | I4: LEITE | J4: LEITE | K4: LEITE | L4: LEITE | M4: LEITE | N4: LEITE | O4: LEITE | P4: LEITE | Q4: LEITE | R4: LEITE | S4: LEITE | T4: LEITE | U4: LEITE | V4: LEITE | W4: LEITE
A5: Ano | B5: Mês | C5: BRASIL | D5: BRASIL | E5: BRASIL | F5: GO | G5: GO | H5: GO | I5: MG | J5: MG | K5: MG | L5: PR | M5: PR | N5: PR | O5: RS | P5: RS | Q5: RS | R5: SC | S5: SC | T5: SC | U5: SP | V5: SP | W5: SP
C6: R$/litro | D6: US$/litro | E6: Deflacionado | F6: R$/litro | G6: US$/litro | H6: Deflacionado | I6: R$/litro | J6: US$/litro | K6: Deflacionado | L6: R$/litro | M6: US$/litro | N6: Deflacionado | O6: R$/litro | P6: US$/litro | Q6: Deflacionado | R6: R$/litro | S6: US$/litro | T6: Deflacionado | U6: R$/litro | V6: US$/litro | W6: Deflacionado
A7: 1990 | B7: JAN
B8: FEV
B9: MAR
B10: ABR
B11: MAI
B12: JUN
B13: JUL
B14: AGO
B15: SET
B16: OUT
B17: NOV
B18: DEZ
A19: 1991 | B19: JAN
B20: FEV
B21: MAR
B22: ABR
B23: MAI
B24: JUN
B25: JUL
B26: AGO
B27: SET
B28: OUT
B29: NOV
B30: DEZ
A31: 1992 | B31: JAN
B32: FEV
B33: MAR
B34: ABR
B35: MAI
B36: JUN
B37: JUL
B38: AGO
B39: SET
B40: OUT
B41: NOV
B42: DEZ
A43: 1993 | B43: JAN
...

Sheet Leite Charts

Sheet Indicadores
C4: BRENT OIL | D4: NATURAL GAS | E4: DIESEL S-10 | F4: DIESEL S-10 | G4: DIESEL S-10 | H4: ETANOL | I4: ETANOL | J4: ETANOL | K4: GASOLINA C | L4: GASOLINA C | M4: GASOLINA C | N4: USD
A5: Ano | B5: Mês | C5: GLOBAL | D5: EUROPE | E5: VAREJO BR | F5: VAREJO BR | G5: VAREJO BR | H5: VAREJO BR | I5: VAREJO BR | J5: VAREJO BR | K5: VAREJO BR | L5: VAREJO BR | M5: VAREJO BR | N5: COMERCIAL
C6: US$/barril | D6: US$/mmbtu | E6: R$/litro | F6: U$/litro | G6: Deflacionado | H6: R$/litro | I6: U$/litro | J6: Deflacionado | K6: R$/litro | L6: U$/litro | M6: Deflacionado | N6: R$/US$
A7: 1990 | B7: JAN | C7: 20.95 | D7: 2.82 | N7: 14.314
B8: FEV | C8: 19.9 | D8: 2.82 | N8: 23.661
B9: MAR | C9: 18.45 | D9: 2.82 | N9: 37.746
B10: ABR | C10: 16.75 | D10: 2.82 | N10: 47.816
B11: MAI | C11: 16.7 | D11: 2.82 | N11: 52.203
B12: JUN | C12: 15.7 | D12: 2.82 | N12: 57.171
B13: JUL | C13: 17.55 | D13: 2.82 | N13: 66.613
B14: AGO | C14: 27.05 | D14: 2.82 | N14: 71.742
B15: SET | C15: 34.1 | D15: 2.82 | N15: 75.803
B16: OUT | C16: 36.05 | D16: 2.82 | N16: 95.443
B17: NOV | C17: 33 | D17: 2.82 | N17: 121.88
B18: DEZ | C18: 28 | D18: 2.82 | N18: 155.516
A19: 1991 | B19: JAN | C19: 23.65 | D19: 3.44 | N19: 220.14
B20: FEV | C20: 19.4 | D20: 3.41 | N20: 223.43
B21: MAR | C21: 19.45 | D21: 3.33 | N21: 238.93
B22: ABR | C22: 19.25 | D22: 3.47 | N22: 260.73
B23: MAI | C23: 19.3 | D23: 3.37 | N23: 284.7
B24: JUN | C24: 18.2 | D24: 3.29 | N24: 312.23
B25: JUL | C25: 19.45 | D25: 3 | N25: 346.57
B26: AGO | C26: 19.75 | D26: 2.98 | N26: 375
B27: SET | C27: 20.5 | D27: 2.97 | N27: 440
B28: OUT | C28: 22.2 | D28: 2.71 | N28: 600
B29: NOV | C29: 21.25 | D29: 2.7 | N29: 755
B30: DEZ | C30: 18.4 | D30: 2.7 | N30: 978
A31: 1992 | B31: JAN | C31: 18.15 | D31: 2.57 | N31: 1197
B32: FEV | C32: 18.1 | D32: 2.5 | N32: 1474
B33: MAR | C33: 17.6 | D33: 2.58 | N33: 1813
B34: ABR | C34: 18.95 | D34: 2.47 | N34: 2217
B35: MAI | C35: 19.9 | D35: 2.49 | N35: 2600
B36: JUN | C36: 21.15 | D36: 2.5 | N36: 3400
B37: JUL | C37: 20.25 | D37: 2.55 | N37: 3850
B38: AGO | C38: 19.75 | D38: 2.56 | N38: 4650
B39: SET | C39: 20.25 | D39: 2.57 | N39: 5758
B40: OUT | C40: 20.3 | D40: 2.63 | N40: 7350.1
B41: NOV | C41: 19.2 | D41: 2.64 | N41: 8872.3
B42: DEZ | C42: 18.15 | D42: 2.64 | N42: 11053.8
A43: 1993 | B43: JAN | C43: 17.4 | D43: 2.76 | N43: 14059.2
...

Sheet XAxis
B2: JAN | C2: JAN | D2: 1990
B3: FEV | C3: FEB | D3: 1991
B4: MAR | C4: MAR | D4: 1992
B5: ABR | C5: APR | D5: 1993
B6: MAI | C6: MAY | D6: 1994
B7: JUN | C7: JUN | D7: 1995
B8: JUL | C8: JUL | D8: 1996
B9: AGO | C9: AUG | D9: 1997
B10: SET | C10: SEP | D10: 1998
B11: OUT | C11: OCT | D11: 1999
B12: NOV | C12: NOV | D12: 2000
B13: DEZ | C13: DEC | D13: 2001
D14: 2002
D15: 2003
D16: 2004
D17: 2005
D18: 2006
D19: 2007
D20: 2008
D21: 2009
D22: 2010
D23: 2011
D24: 2012
D25: 2013
... D34: 2022
